<robot
  name="Assem1.SLDASM">
  <link
    name="base_link">
    <inertial>
      <origin
        xyz="0.0332765957742424 -0.156512477716097 0.0925665357628855"
        rpy="0 0 0" />
      <mass
        value="0.0764186268773801" />
      <inertia
        ixx="0.000159184039997052"
        ixy="3.64651046457606E-06"
        ixz="1.98156516108087E-12"
        iyy="6.11923069210277E-06"
        iyz="3.35609708105055E-11"
        izz="0.000159231167066698" />
    </inertial>
    <visual>
      <origin
        xyz="0 0 0"
        rpy="0 0 0" />
      <geometry>
        <mesh
          filename="model://Assem1.SLDASM/meshes/base_link.STL" />
      </geometry>
      <material
        name="">
        <color
          rgba="0.831372549019608 0.831372549019608 0.831372549019608 1" />
      </material>
    </visual>
    <collision>
      <origin
        xyz="0 0 0"
        rpy="0 0 0" />
      <geometry>
        <mesh
          filename="model://Assem1.SLDASM/meshes/base_link.STL" />
      </geometry>
    </collision>
  </link>
  <link
    name="L1">
    <inertial>
      <origin
        xyz="0.0126915237074628 -0.0709328402469596 0.0463266287271005"
        rpy="0 0 0" />
      <mass
        value="0.0764186268773801" />
      <inertia
        ixx="0.000159184039997051"
        ixy="3.05305510988943E-06"
        ixz="-1.99396415821454E-06"
        iyy="5.19006494021059E-05"
        iyz="-7.00980981879337E-05"
        izz="0.000113449748356695" />
    </inertial>
    <visual>
      <origin
        xyz="0 0 0"
        rpy="0 0 0" />
      <geometry>
        <mesh
          filename="model://Assem1.SLDASM/meshes/L1.STL" />
      </geometry>
      <material
        name="">
        <color
          rgba="0.831372549019608 0.831372549019608 0.831372549019608 1" />
      </material>
    </visual>
    <collision>
      <origin
        xyz="0 0 0"
        rpy="0 0 0" />
      <geometry>
        <mesh
          filename="model://Assem1.SLDASM/meshes/L1.STL" />
      </geometry>
    </collision>
  </link>
  <joint
    name="J1"
    type="revolute">
    <origin
      xyz="0.0215850720667796 -0.234351616325769 0.0925665243584146"
      rpy="0.578555123516184 0 0" />
    <parent
      link="base_link" />
    <child
      link="L1" />
    <axis
      xyz="-1 0 0" />
  </joint>
</robot>
